nohup: ignoring input
[2025-02-05 18:47:23 +0000] [10996] [INFO] Starting gunicorn 23.0.0
[2025-02-05 18:47:23 +0000] [10996] [INFO] Listening at: http://0.0.0.0:5000 (10996)
[2025-02-05 18:47:23 +0000] [10996] [INFO] Using worker: sync
[2025-02-05 18:47:23 +0000] [10997] [INFO] Booting worker with pid: 10997
loading Roboflow workspace...
loading Roboflow project...
[2025-02-05 18:50:22,063] ERROR in app: Exception on /userappointment [GET]
Traceback (most recent call last):
  File "/home/ubuntu/Skintellect/venv/lib/python3.12/site-packages/flask/app.py", line 1511, in wsgi_app
    response = self.full_dispatch_request()
               ^^^^^^^^^^^^^^^^^^^^^^^^^^^^
  File "/home/ubuntu/Skintellect/venv/lib/python3.12/site-packages/flask/app.py", line 919, in full_dispatch_request
    rv = self.handle_user_exception(e)
         ^^^^^^^^^^^^^^^^^^^^^^^^^^^^^
  File "/home/ubuntu/Skintellect/venv/lib/python3.12/site-packages/flask/app.py", line 917, in full_dispatch_request
    rv = self.dispatch_request()
         ^^^^^^^^^^^^^^^^^^^^^^^
  File "/home/ubuntu/Skintellect/venv/lib/python3.12/site-packages/flask/app.py", line 902, in dispatch_request
    return self.ensure_sync(self.view_functions[rule.endpoint])(**view_args)  # type: ignore[no-any-return]
           ^^^^^^^^^^^^^^^^^^^^^^^^^^^^^^^^^^^^^^^^^^^^^^^^^^^^^^^^^^^^^^^^^
  File "/home/ubuntu/Skintellect/app.py", line 312, in userappoint
    user = session['username']
           ~~~~~~~^^^^^^^^^^^^
  File "/home/ubuntu/Skintellect/venv/lib/python3.12/site-packages/flask/sessions.py", line 86, in __getitem__
    return super().__getitem__(key)
           ^^^^^^^^^^^^^^^^^^^^^^^^
KeyError: 'username'
[2025-02-05 18:57:59 +0000] [10996] [INFO] Handling signal: hup
[2025-02-05 18:57:59 +0000] [10996] [INFO] Hang up: Master
[2025-02-05 18:57:59 +0000] [11576] [INFO] Booting worker with pid: 11576
[2025-02-05 18:57:59 +0000] [10996] [ERROR] Worker (pid:10997) was sent SIGHUP!
loading Roboflow workspace...
loading Roboflow project...
[2025-02-05 19:44:00,294] ERROR in app: Exception on /userappointment [GET]
Traceback (most recent call last):
  File "/home/ubuntu/Skintellect/venv/lib/python3.12/site-packages/flask/app.py", line 1511, in wsgi_app
    response = self.full_dispatch_request()
               ^^^^^^^^^^^^^^^^^^^^^^^^^^^^
  File "/home/ubuntu/Skintellect/venv/lib/python3.12/site-packages/flask/app.py", line 919, in full_dispatch_request
    rv = self.handle_user_exception(e)
         ^^^^^^^^^^^^^^^^^^^^^^^^^^^^^
  File "/home/ubuntu/Skintellect/venv/lib/python3.12/site-packages/flask/app.py", line 917, in full_dispatch_request
    rv = self.dispatch_request()
         ^^^^^^^^^^^^^^^^^^^^^^^
  File "/home/ubuntu/Skintellect/venv/lib/python3.12/site-packages/flask/app.py", line 902, in dispatch_request
    return self.ensure_sync(self.view_functions[rule.endpoint])(**view_args)  # type: ignore[no-any-return]
           ^^^^^^^^^^^^^^^^^^^^^^^^^^^^^^^^^^^^^^^^^^^^^^^^^^^^^^^^^^^^^^^^^
  File "/home/ubuntu/Skintellect/app.py", line 312, in userappoint
    def userappoint():
               ^^^^^^^^
  File "/home/ubuntu/Skintellect/venv/lib/python3.12/site-packages/flask/sessions.py", line 86, in __getitem__
    return super().__getitem__(key)
           ^^^^^^^^^^^^^^^^^^^^^^^^
KeyError: 'username'
[2025-02-05 19:44:22,904] ERROR in app: Exception on /userappointment [GET]
Traceback (most recent call last):
  File "/home/ubuntu/Skintellect/venv/lib/python3.12/site-packages/flask/app.py", line 1511, in wsgi_app
    response = self.full_dispatch_request()
               ^^^^^^^^^^^^^^^^^^^^^^^^^^^^
  File "/home/ubuntu/Skintellect/venv/lib/python3.12/site-packages/flask/app.py", line 919, in full_dispatch_request
    rv = self.handle_user_exception(e)
         ^^^^^^^^^^^^^^^^^^^^^^^^^^^^^
  File "/home/ubuntu/Skintellect/venv/lib/python3.12/site-packages/flask/app.py", line 917, in full_dispatch_request
    rv = self.dispatch_request()
         ^^^^^^^^^^^^^^^^^^^^^^^
  File "/home/ubuntu/Skintellect/venv/lib/python3.12/site-packages/flask/app.py", line 902, in dispatch_request
    return self.ensure_sync(self.view_functions[rule.endpoint])(**view_args)  # type: ignore[no-any-return]
           ^^^^^^^^^^^^^^^^^^^^^^^^^^^^^^^^^^^^^^^^^^^^^^^^^^^^^^^^^^^^^^^^^
  File "/home/ubuntu/Skintellect/app.py", line 312, in userappoint
    def userappoint():
               ^^^^^^^^
  File "/home/ubuntu/Skintellect/venv/lib/python3.12/site-packages/flask/sessions.py", line 86, in __getitem__
    return super().__getitem__(key)
           ^^^^^^^^^^^^^^^^^^^^^^^^
KeyError: 'username'
[2025-02-06 03:54:31,338] ERROR in app: Exception on /userappointment [GET]
Traceback (most recent call last):
  File "/home/ubuntu/Skintellect/venv/lib/python3.12/site-packages/flask/app.py", line 1511, in wsgi_app
    response = self.full_dispatch_request()
               ^^^^^^^^^^^^^^^^^^^^^^^^^^^^
  File "/home/ubuntu/Skintellect/venv/lib/python3.12/site-packages/flask/app.py", line 919, in full_dispatch_request
    rv = self.handle_user_exception(e)
         ^^^^^^^^^^^^^^^^^^^^^^^^^^^^^
  File "/home/ubuntu/Skintellect/venv/lib/python3.12/site-packages/flask/app.py", line 917, in full_dispatch_request
    rv = self.dispatch_request()
         ^^^^^^^^^^^^^^^^^^^^^^^
  File "/home/ubuntu/Skintellect/venv/lib/python3.12/site-packages/flask/app.py", line 902, in dispatch_request
    return self.ensure_sync(self.view_functions[rule.endpoint])(**view_args)  # type: ignore[no-any-return]
           ^^^^^^^^^^^^^^^^^^^^^^^^^^^^^^^^^^^^^^^^^^^^^^^^^^^^^^^^^^^^^^^^^
  File "/home/ubuntu/Skintellect/app.py", line 312, in userappoint
    def userappoint():
               ^^^^^^^^
  File "/home/ubuntu/Skintellect/venv/lib/python3.12/site-packages/flask/sessions.py", line 86, in __getitem__
    return super().__getitem__(key)
           ^^^^^^^^^^^^^^^^^^^^^^^^
KeyError: 'username'
[2025-02-06 06:21:33,732] ERROR in app: Exception on /userappointment [HEAD]
Traceback (most recent call last):
  File "/home/ubuntu/Skintellect/venv/lib/python3.12/site-packages/flask/app.py", line 1511, in wsgi_app
    response = self.full_dispatch_request()
               ^^^^^^^^^^^^^^^^^^^^^^^^^^^^
  File "/home/ubuntu/Skintellect/venv/lib/python3.12/site-packages/flask/app.py", line 919, in full_dispatch_request
    rv = self.handle_user_exception(e)
         ^^^^^^^^^^^^^^^^^^^^^^^^^^^^^
  File "/home/ubuntu/Skintellect/venv/lib/python3.12/site-packages/flask/app.py", line 917, in full_dispatch_request
    rv = self.dispatch_request()
         ^^^^^^^^^^^^^^^^^^^^^^^
  File "/home/ubuntu/Skintellect/venv/lib/python3.12/site-packages/flask/app.py", line 902, in dispatch_request
    return self.ensure_sync(self.view_functions[rule.endpoint])(**view_args)  # type: ignore[no-any-return]
           ^^^^^^^^^^^^^^^^^^^^^^^^^^^^^^^^^^^^^^^^^^^^^^^^^^^^^^^^^^^^^^^^^
  File "/home/ubuntu/Skintellect/app.py", line 312, in userappoint
    def userappoint():
               ^^^^^^^^
  File "/home/ubuntu/Skintellect/venv/lib/python3.12/site-packages/flask/sessions.py", line 86, in __getitem__
    return super().__getitem__(key)
           ^^^^^^^^^^^^^^^^^^^^^^^^
KeyError: 'username'
[2025-02-06 06:21:34,770] ERROR in app: Exception on /userappointment [GET]
Traceback (most recent call last):
  File "/home/ubuntu/Skintellect/venv/lib/python3.12/site-packages/flask/app.py", line 1511, in wsgi_app
    response = self.full_dispatch_request()
               ^^^^^^^^^^^^^^^^^^^^^^^^^^^^
  File "/home/ubuntu/Skintellect/venv/lib/python3.12/site-packages/flask/app.py", line 919, in full_dispatch_request
    rv = self.handle_user_exception(e)
         ^^^^^^^^^^^^^^^^^^^^^^^^^^^^^
  File "/home/ubuntu/Skintellect/venv/lib/python3.12/site-packages/flask/app.py", line 917, in full_dispatch_request
    rv = self.dispatch_request()
         ^^^^^^^^^^^^^^^^^^^^^^^
  File "/home/ubuntu/Skintellect/venv/lib/python3.12/site-packages/flask/app.py", line 902, in dispatch_request
    return self.ensure_sync(self.view_functions[rule.endpoint])(**view_args)  # type: ignore[no-any-return]
           ^^^^^^^^^^^^^^^^^^^^^^^^^^^^^^^^^^^^^^^^^^^^^^^^^^^^^^^^^^^^^^^^^
  File "/home/ubuntu/Skintellect/app.py", line 312, in userappoint
    def userappoint():
               ^^^^^^^^
  File "/home/ubuntu/Skintellect/venv/lib/python3.12/site-packages/flask/sessions.py", line 86, in __getitem__
    return super().__getitem__(key)
           ^^^^^^^^^^^^^^^^^^^^^^^^
KeyError: 'username'
[2025-02-06 06:25:20,540] ERROR in app: Exception on /userappointment [GET]
Traceback (most recent call last):
  File "/home/ubuntu/Skintellect/venv/lib/python3.12/site-packages/flask/app.py", line 1511, in wsgi_app
    response = self.full_dispatch_request()
               ^^^^^^^^^^^^^^^^^^^^^^^^^^^^
  File "/home/ubuntu/Skintellect/venv/lib/python3.12/site-packages/flask/app.py", line 919, in full_dispatch_request
    rv = self.handle_user_exception(e)
         ^^^^^^^^^^^^^^^^^^^^^^^^^^^^^
  File "/home/ubuntu/Skintellect/venv/lib/python3.12/site-packages/flask/app.py", line 917, in full_dispatch_request
    rv = self.dispatch_request()
         ^^^^^^^^^^^^^^^^^^^^^^^
  File "/home/ubuntu/Skintellect/venv/lib/python3.12/site-packages/flask/app.py", line 902, in dispatch_request
    return self.ensure_sync(self.view_functions[rule.endpoint])(**view_args)  # type: ignore[no-any-return]
           ^^^^^^^^^^^^^^^^^^^^^^^^^^^^^^^^^^^^^^^^^^^^^^^^^^^^^^^^^^^^^^^^^
  File "/home/ubuntu/Skintellect/app.py", line 312, in userappoint
    def userappoint():
               ^^^^^^^^
  File "/home/ubuntu/Skintellect/venv/lib/python3.12/site-packages/flask/sessions.py", line 86, in __getitem__
    return super().__getitem__(key)
           ^^^^^^^^^^^^^^^^^^^^^^^^
KeyError: 'username'
[2025-02-06 08:50:54,632] ERROR in app: Exception on /userappointment [GET]
Traceback (most recent call last):
  File "/home/ubuntu/Skintellect/venv/lib/python3.12/site-packages/flask/app.py", line 1511, in wsgi_app
    response = self.full_dispatch_request()
               ^^^^^^^^^^^^^^^^^^^^^^^^^^^^
  File "/home/ubuntu/Skintellect/venv/lib/python3.12/site-packages/flask/app.py", line 919, in full_dispatch_request
    rv = self.handle_user_exception(e)
         ^^^^^^^^^^^^^^^^^^^^^^^^^^^^^
  File "/home/ubuntu/Skintellect/venv/lib/python3.12/site-packages/flask/app.py", line 917, in full_dispatch_request
    rv = self.dispatch_request()
         ^^^^^^^^^^^^^^^^^^^^^^^
  File "/home/ubuntu/Skintellect/venv/lib/python3.12/site-packages/flask/app.py", line 902, in dispatch_request
    return self.ensure_sync(self.view_functions[rule.endpoint])(**view_args)  # type: ignore[no-any-return]
           ^^^^^^^^^^^^^^^^^^^^^^^^^^^^^^^^^^^^^^^^^^^^^^^^^^^^^^^^^^^^^^^^^
  File "/home/ubuntu/Skintellect/app.py", line 312, in userappoint
    def userappoint():
               ^^^^^^^^
  File "/home/ubuntu/Skintellect/venv/lib/python3.12/site-packages/flask/sessions.py", line 86, in __getitem__
    return super().__getitem__(key)
           ^^^^^^^^^^^^^^^^^^^^^^^^
KeyError: 'username'
[2025-02-06 12:38:02,598] ERROR in app: Exception on /userappointment [GET]
Traceback (most recent call last):
  File "/home/ubuntu/Skintellect/venv/lib/python3.12/site-packages/flask/app.py", line 1511, in wsgi_app
    response = self.full_dispatch_request()
               ^^^^^^^^^^^^^^^^^^^^^^^^^^^^
  File "/home/ubuntu/Skintellect/venv/lib/python3.12/site-packages/flask/app.py", line 919, in full_dispatch_request
    rv = self.handle_user_exception(e)
         ^^^^^^^^^^^^^^^^^^^^^^^^^^^^^
  File "/home/ubuntu/Skintellect/venv/lib/python3.12/site-packages/flask/app.py", line 917, in full_dispatch_request
    rv = self.dispatch_request()
         ^^^^^^^^^^^^^^^^^^^^^^^
  File "/home/ubuntu/Skintellect/venv/lib/python3.12/site-packages/flask/app.py", line 902, in dispatch_request
    return self.ensure_sync(self.view_functions[rule.endpoint])(**view_args)  # type: ignore[no-any-return]
           ^^^^^^^^^^^^^^^^^^^^^^^^^^^^^^^^^^^^^^^^^^^^^^^^^^^^^^^^^^^^^^^^^
  File "/home/ubuntu/Skintellect/app.py", line 312, in userappoint
    def userappoint():
               ^^^^^^^^
  File "/home/ubuntu/Skintellect/venv/lib/python3.12/site-packages/flask/sessions.py", line 86, in __getitem__
    return super().__getitem__(key)
           ^^^^^^^^^^^^^^^^^^^^^^^^
KeyError: 'username'
[2025-02-06 17:56:42,102] ERROR in app: Exception on /userappointment [GET]
Traceback (most recent call last):
  File "/home/ubuntu/Skintellect/venv/lib/python3.12/site-packages/flask/app.py", line 1511, in wsgi_app
    response = self.full_dispatch_request()
               ^^^^^^^^^^^^^^^^^^^^^^^^^^^^
  File "/home/ubuntu/Skintellect/venv/lib/python3.12/site-packages/flask/app.py", line 919, in full_dispatch_request
    rv = self.handle_user_exception(e)
         ^^^^^^^^^^^^^^^^^^^^^^^^^^^^^
  File "/home/ubuntu/Skintellect/venv/lib/python3.12/site-packages/flask/app.py", line 917, in full_dispatch_request
    rv = self.dispatch_request()
         ^^^^^^^^^^^^^^^^^^^^^^^
  File "/home/ubuntu/Skintellect/venv/lib/python3.12/site-packages/flask/app.py", line 902, in dispatch_request
    return self.ensure_sync(self.view_functions[rule.endpoint])(**view_args)  # type: ignore[no-any-return]
           ^^^^^^^^^^^^^^^^^^^^^^^^^^^^^^^^^^^^^^^^^^^^^^^^^^^^^^^^^^^^^^^^^
  File "/home/ubuntu/Skintellect/app.py", line 312, in userappoint
    def userappoint():
               ^^^^^^^^
  File "/home/ubuntu/Skintellect/venv/lib/python3.12/site-packages/flask/sessions.py", line 86, in __getitem__
    return super().__getitem__(key)
           ^^^^^^^^^^^^^^^^^^^^^^^^
KeyError: 'username'
[2025-02-06 17:56:47,051] ERROR in app: Exception on /userappointment [GET]
Traceback (most recent call last):
  File "/home/ubuntu/Skintellect/venv/lib/python3.12/site-packages/flask/app.py", line 1511, in wsgi_app
    response = self.full_dispatch_request()
               ^^^^^^^^^^^^^^^^^^^^^^^^^^^^
  File "/home/ubuntu/Skintellect/venv/lib/python3.12/site-packages/flask/app.py", line 919, in full_dispatch_request
    rv = self.handle_user_exception(e)
         ^^^^^^^^^^^^^^^^^^^^^^^^^^^^^
  File "/home/ubuntu/Skintellect/venv/lib/python3.12/site-packages/flask/app.py", line 917, in full_dispatch_request
    rv = self.dispatch_request()
         ^^^^^^^^^^^^^^^^^^^^^^^
  File "/home/ubuntu/Skintellect/venv/lib/python3.12/site-packages/flask/app.py", line 902, in dispatch_request
    return self.ensure_sync(self.view_functions[rule.endpoint])(**view_args)  # type: ignore[no-any-return]
           ^^^^^^^^^^^^^^^^^^^^^^^^^^^^^^^^^^^^^^^^^^^^^^^^^^^^^^^^^^^^^^^^^
  File "/home/ubuntu/Skintellect/app.py", line 312, in userappoint
    def userappoint():
               ^^^^^^^^
  File "/home/ubuntu/Skintellect/venv/lib/python3.12/site-packages/flask/sessions.py", line 86, in __getitem__
    return super().__getitem__(key)
           ^^^^^^^^^^^^^^^^^^^^^^^^
KeyError: 'username'
